{"version":3,"sources":["js/01-try-catch.js"],"names":["console","log","myVar","error"],"mappings":";AAiBA,IACEA,QAAQC,IAAI,uBAEZC,MAEAF,QAAQC,IAAI,0BACZ,MAAOE,GACPH,QAAQC,IAAI,WAGdD,QAAQC,IAAI","file":"01-try-catch.3d54a963.js","sourceRoot":"..\\src","sourcesContent":["// Обработка ошибок с try...catch\n//  - Синтаксис\n//  - Какие ошибки ловит\n//    - ❌ ошибки парсинга (parsing errors)\n//    - ✅ ошибки выполнения (runtime errors)\n//  - Ловит только ошибки в синхронном коде\n//    - Как словить ошибку в асинхронном коде\n//  - Объект ошибки\n//    - name\n//    - message\n//    - stack\n          //   - error.name - имя ошибки,\n          //   - error.message - сообщение об ошибке,\n          //   - error.stack - выводит вид стэка вызова функций на момент,\n          //     когда случилась ошибка(stack trace).\n//  - Блок catch без объекта ошибки\n\ntry {\n  console.log('Внутри try до myVar');\n\n  myVar;\n\n  console.log('Внутри try после myVar');\n} catch (error) {\n  console.log('Ошибка!');\n}\n\nconsole.log('После try...catch');\n"]}